Workbook
Name Segment_Année: #N/A
Name Segment_nom_departement: #N/A

Sheet ID DEP
A1: code_departement | B1: nom_departement | C1: code_region | D1: nom_region
A2: 01 | B2: Ain | C2: 84 | D2: Auvergne-Rhône-Alpes
A3: 02 | B3: Aisne | C3: 32 | D3: Hauts-de-France
A4: 03 | B4: Allier | C4: 84 | D4: Auvergne-Rhône-Alpes
A5: 04 | B5: Alpes-de-Haute-Provence | C5: 93 | D5: Provence-Alpes-Côte d'Azur
A6: 05 | B6: Hautes-Alpes | C6: 93 | D6: Provence-Alpes-Côte d'Azur
A7: 06 | B7: Alpes-Maritimes | C7: 93 | D7: Provence-Alpes-Côte d'Azur
A8: 07 | B8: Ardèche | C8: 84 | D8: Auvergne-Rhône-Alpes
A9: 08 | B9: Ardennes | C9: 44 | D9: Grand Est
A10: 09 | B10: Ariège | C10: 76 | D10: Occitanie
A11: 10 | B11: Aube | C11: 44 | D11: Grand Est
A12: 11 | B12: Aude | C12: 76 | D12: Occitanie
A13: 12 | B13: Aveyron | C13: 76 | D13: Occitanie
... A102: 976 | B102: Mayotte | C102: 6 | D102: Mayotte

Sheet ID DATE
A1: Année
A2: 2009
A3: 2011
A4: 2013
A5: 2015
A6: 2017
A7: 2019
A8: 2021

Sheet BD POPULATION
A1: ANNEE | B1: CODE_DEPT | C1: NOM_DEPT | D1: POPULATION HOMME | E1: POPULATION FEMME
A2: 2021 | B2: 01 | C2: Ain | D2: 327390 | E2: 335812
A3: 2021 | B3: 02 | C3: Aisne | D3: 257606 | E3: 269862
A4: 2021 | B4: 03 | C4: Allier | D4: 160806 | E4: 174066
A5: 2021 | B5: 04 | C5: Alpes-de-Haute-Provence | D5: 80520 | E5: 85557
A6: 2021 | B6: 05 | C6: Hautes-Alpes | D6: 68662 | E6: 72314
A7: 2021 | B7: 06 | C7: Alpes-Maritimes | D7: 522072 | E7: 581869
A8: 2021 | B8: 07 | C8: Ardèche | D8: 161801 | E8: 169614
A9: 2021 | B9: 08 | C9: Ardennes | D9: 131443 | E9: 137416
A10: 2021 | B10: 09 | C10: Ariège | D10: 75627 | E10: 78969
A11: 2021 | B11: 10 | C11: Aube | D11: 151657 | E11: 159672
A12: 2021 | B12: 11 | C12: Aude | D12: 180864 | E12: 195164
A13: 2021 | B13: 12 | C13: Aveyron | D13: 138046 | E13: 141603
... A97: 2021 | B97: 95 | C97: Val-d'Oise | D97: 611448 | E97: 645159
A98: 2021 | B98: 971 | C98: Guadeloupe | D98: 175788 | E98: 208527
A99: 2021 | B99: 972 | C99: Martinique | D99: 164919 | E99: 195830
A100: 2021 | B100: 973 | C100: Guyane | D100: 139465 | E100: 147153
A101: 2021 | B101: 974 | C101: La Réunion | D101: 415138 | E101: 456019
A102: 2021 | B102: 976 | C102: Mayotte | D102: 137757 | E102: 151282
A103: 2019 | B103: 01 | C103: Ain | D103: 321857 | E103: 330575
A104: 2019 | B104: 02 | C104: Aisne | D104: 259129 | E104: 272216
A105: 2019 | B105: 03 | C105: Allier | D105: 161193 | E105: 174782
A106: 2019 | B106: 04 | C106: Alpes-de-Haute-Provence | D106: 79843 | E106: 84465
A107: 2019 | B107: 05 | C107: Hautes-Alpes | D107: 68958 | E107: 72262
A108: 2019 | B108: 06 | C108: Alpes-Maritimes | D108: 517600 | E108: 576683
A109: 2019 | B109: 07 | C109: Ardèche | D109: 160249 | E109: 168029
A110: 2019 | B110: 08 | C110: Ardennes | D110: 132155 | E110: 138427
A111: 2019 | B111: 09 | C111: Ariège | D111: 75049 | E111: 78238
A112: 2019 | B112: 10 | C112: Aube | D112: 150897 | E112: 159345
A113: 2019 | B113: 11 | C113: Aude | D113: 179865 | E113: 194205
A114: 2019 | B114: 12 | C114: Aveyron | D114: 138031 | E114: 141564
... A198: 2019 | B198: 95 | C198: Val-d'Oise | D198: 607316 | E198: 642358
A199: 2019 | B199: 971 | C199: Guadeloupe | D199: 175726 | E199: 208513
A200: 2019 | B200: 972 | C200: Martinique | D200: 166945 | E200: 197563
A201: 2019 | B201: 973 | C201: Guyane | D201: 137260 | E201: 144418
A202: 2019 | B202: 974 | C202: La Réunion | D202: 411393 | E202: 449817
A203: 2019 | B203: 976 | C203: Mayotte | D203: 128482 | E203: 141097
A204: 2017 | B204: 01 | C204: Ain | D204: 317292 | E204: 326058
A205: 2017 | B205: 02 | C205: Aisne | D205: 260669 | E205: 273821
A206: 2017 | B206: 03 | C206: Allier | D206: 161855 | E206: 176133
...

Sheet BD TONNAGE
A1: ANNEE | B1: CODE_DEPT | C1: NOM_DEPT | D1: TYPE_DECHET | E1: TYPE_VALO | F1: TONNAGE | G1: TYPE_VALO2
A2: 2009 | B2: 01 | C2: Ain | D2: Ordures ménagères résiduelles | E2: Incinération avec récupération d'énergie | F2: 98575.13 | G2: Valorisation énergétique
A3: 2009 | B3: 01 | C3: Ain | D3: Ordures ménagères résiduelles | E3: Stockage | F3: 35633.56 | G3: Élimination
A4: 2009 | B4: 01 | C4: Ain | D4: Verre | E4: Valorisation matière | F4: 19661 | G4: Valorisation matière
A5: 2009 | B5: 01 | C5: Ain | D5: Emballages et papier | E5: Valorisation matière | F5: 22998.7 | G5: Valorisation matière
A6: 2009 | B6: 01 | C6: Ain | D6: Emballages et papier | E6: Stockage | F6: 5.28 | G6: Élimination
A7: 2009 | B7: 01 | C7: Ain | D7: Encombrants | E7: Incinération avec récupération d'énergie | F7: 140.34 | G7: Valorisation énergétique
A8: 2009 | B8: 01 | C8: Ain | D8: Encombrants | E8: Stockage | F8: 4.95 | G8: Élimination
A9: 2009 | B9: 01 | C9: Ain | D9: Encombrants | E9: Non précisé | F9: 87.72 | G9: INCONNU
A10: 2009 | B10: 01 | C10: Ain | D10: Déchets dangereux (y.c. DEEE) | E10: Incinération avec récupération d'énergie | F10: 0.01 | G10: Valorisation énergétique
A11: 2009 | B11: 01 | C11: Ain | D11: Déchets dangereux (y.c. DEEE) | E11: Non précisé | F11: 3.39 | G11: INCONNU
A12: 2009 | B12: 01 | C12: Ain | D12: Collectes séparées hors gravats | E12: Valorisation matière | F12: 4.88 | G12: Valorisation matière
A13: 2009 | B13: 03 | C13: Allier | D13: Ordures ménagères résiduelles | E13: Incinération avec récupération d'énergie | F13: 33016.14 | G13: Valorisation énergétique
... A7721: 2021 | B7721: 84 | C7721: Vaucluse | D7721: Collectes séparées hors gravats | E7721: Stockage | F7721: 139.27 | G7721: Élimination

Sheet CARTE
A1: DÉPARTEMENT | B1: TONNAGE / HABITANT
A2: =TCD!F38 -> Ain | B2: =TCD!I38 -> 0.27897078
A3: =TCD!F39 -> Aisne | B3: =TCD!I39 -> 0.35452531
A4: =TCD!F40 -> Allier | B4: =TCD!I40 -> 0.35808549
A5: =TCD!F41 -> Alpes-de-Haute-Provence | B5: =TCD!I41 -> 0.43174481
A6: =TCD!F42 -> Alpes-Maritimes | B6: =TCD!I42 -> 0.53270531
A7: =TCD!F43 -> Ardèche | B7: =TCD!I43 -> 0.33254002
A8: =TCD!F44 -> Ardennes | B8: =TCD!I44 -> 0.35911006
A9: =TCD!F45 -> Ariège | B9: =TCD!I45 -> 0.4254361
A10: =TCD!F46 -> Aube | B10: =TCD!I46 -> 0.37852255
A11: =TCD!F47 -> Aude | B11: =TCD!I47 -> 0.42224412
A12: =TCD!F48 -> Aveyron | B12: =TCD!I48 -> 0.32783854
A13: =TCD!F49 -> Bas-Rhin | B13: =TCD!I49 -> 0.31406324
... A102: =TCD!F138 -> Yvelines | B102: =TCD!I138 -> 0.38703092

Sheet TCD
A1: nom_departement | B1: All
A2: Année | B2: All
A4: Somme de TONNAGE | B4: Somme de POPULATION HOMME | C4: Somme de POPULATION FEMME | D4: POPULATION GLOBAL | E4: TONNAGE / HAB | G4: HOMME | H4: FEMME | J4: HOMME | K4: FEMME
A5: 1.733799e+08 | B5: 224079469 | C5: 238875211 | D5: =$B$5+$C$5 -> 462954680 | E5: =$A$5 / $D$5 -> 0.37450727 | G5: =B5 / $D$5 -> 0.48402031 | H5: =C5 / $D$5 -> 0.51597969 | J5: =D5/B5 -> 2.066029 | K5: =D5/C5 -> 1.9380608
A11: nom_departement | B11: All
A12: Année | B12: All
A14: Étiquettes de lignes | B14: Somme de TONNAGE
A15: INCONNU | B15: 0.10277099
A16: Élimination | B16: 0.22053073
A17: Valorisation matière | B17: 0.23382382
A18: Valorisation énergétique | B18: 0.44287447
A19: Total général | B19: 1
A24: nom_departement | B24: All
A25: Année | B25: All
A27: Étiquettes de lignes | B27: Somme de TONNAGE
A28: Ordures ménagères résiduelles | B28: 0.77147855
A29: Emballages et papier | B29: 0.14024242
A30: Verre | B30: 0.088279032
A31: Total général | B31: 1
A37: Étiquettes de lignes | B37: Somme de TONNAGE | C37: Somme de POPULATION HOMME | D37: Somme de POPULATION FEMME | F37: DÉPARTEMENT | G37: TONNAGE | H37: POPULATION | I37: TONNAGE / HABITANT
A38: Ain | B38: 1228318.9 | C38: 2174473 | D38: 2228565 | F38: =A38 -> Ain | G38: =B38 -> 1228318.9 | H38: =C38+D38 -> 4403038 | I38: =G38/H38 -> 0.27897078
A39: Aisne | B39: 1330604.8 | C39: 1828881 | D39: 1924320 | F39: =A39 -> Aisne | G39: =B39 -> 1330604.8 | H39: =C39+D39 -> 3753201 | I39: =G39/H39 -> 0.35452531
A40: Allier | B40: 852119.56 | C40: 1141134 | D40: 1238520 | F40: =A40 -> Allier | G40: =B40 -> 852119.56 | H40: =C40+D40 -> 2379654 | I40: =G40/H40 -> 0.35808549
A41: Alpes-de-Haute-Provence | B41: 491508.65 | C41: 552702 | D41: 585722 | F41: =A41 -> Alpes-de-Haute-Provence | G41: =B41 -> 491508.65 | H41: =C41+D41 -> 1138424 | I41: =G41/H41 -> 0.43174481
A42: Alpes-Maritimes | B42: 4051271.3 | C42: 3599373 | D42: 4005716 | F42: =A42 -> Alpes-Maritimes | G42: =B42 -> 4051271.3 | H42: =C42+D42 -> 7605089 | I42: =G42/H42 -> 0.53270531
A43: Ardèche | B43: 751822.43 | C43: 1102399 | D43: 1158449 | F43: =A43 -> Ardèche | G43: =B43 -> 751822.43 | H43: =C43+D43 -> 2260848 | I43: =G43/H43 -> 0.33254002
A44: Ardennes | B44: 695985.83 | C44: 947296 | D44: 990789 | F44: =A44 -> Ardennes | G44: =B44 -> 695985.83 | H44: =C44+D44 -> 1938085 | I44: =G44/H44 -> 0.35911006
A45: Ariège | B45: 455055.81 | C45: 522881 | D45: 546741 | F45: =A45 -> Ariège | G45: =B45 -> 455055.81 | H45: =C45+D45 -> 1069622 | I45: =G45/H45 -> 0.4254361
A46: Aube | B46: 815535.54 | C46: 1046629 | D46: 1107894 | F46: =A46 -> Aube | G46: =B46 -> 815535.54 | H46: =C46+D46 -> 2154523 | I46: =G46/H46 -> 0.37852255
A47: Aude | B47: 1083537.1 | C47: 1235192 | D47: 1330947 | F47: =A47 -> Aude | G47: =B47 -> 1083537.1 | H47: =C47+D47 -> 2566139 | I47: =G47/H47 -> 0.42224412
A48: Aveyron | B48: 638701.61 | C48: 958096 | D48: 990124 | F48: =A48 -> Aveyron | G48: =B48 -> 638701.61 | H48: =C48+D48 -> 1948220 | I48: =G48/H48 -> 0.32783854
A49: Bas-Rhin | B49: 2461660.3 | C49: 3816440 | D49: 4021664 | F49: =A49 -> Bas-Rhin | G49: =B49 -> 2461660.3 | H49: =C49+D49 -> 7838104 | I49: =G49/H49 -> 0.31406324
... A138: Yvelines | B138: 3874105.2 | C138: 4877145 | D138: 5132663 | F138: =A138 -> Yvelines | G138: =B138 -> 3874105.2 | H138: =C138+D138 -> 10009808 | I138: =G138/H138 -> 0.38703092
A139: Total général | B139: 1.733799e+08 | C139: 224079469 | D139: 238875211
A144: nom_departement | B144: All
A145: TYPE_VALO2 | B145: (Plusieurs éléments)
A147: Année | B147: Somme de TONNAGE
A148: 2009 | B148: 16112423
A149: 2011 | B149: 16456471
A150: 2013 | B150: 16234609
...

Sheet DASHBOARD
A1: Dans quelle mesure la structure démographique et la répartition territoriale influencent-elles l'évolution du tonnage des déchets et l'efficacité des modes de valorisation en France entre 2009 et 2021 ?
B13: =TCD!$A$5 -> 1.733799e+08 | F13: =TCD!$D$5 -> 462954680 | J13: =TCD!$E$5 -> 0.37450727
